Workbook

Sheet Integrated_dataSet
A1: State | B1: Year | C1: Deaths | D1: State Year Key | E1: Population | F1: Rate
A2: Alabama | B2: 2009 | C2: 755 | D2: Alabama 2009 | E2: 4713550 | F2: 0.00016017651
A3: Alabama | B3: 2010 | C3: 809 | D3: Alabama 2010 | E3: 4862140 | F3: 0.00016638764
A4: Alabama | B4: 2011 | C4: 776 | D4: Alabama 2011 | E4: 5081072 | F4: 0.00015272368
A5: Alabama | B5: 2012 | C5: 761 | D5: Alabama 2012 | E5: 4866478 | F5: 0.00015637593
A6: Alabama | B6: 2013 | C6: 861 | D6: Alabama 2013 | E6: 4876320 | F6: 0.00017656758
A7: Alabama | B7: 2014 | C7: 887 | D7: Alabama 2014 | E7: 4622427 | F7: 0.00019189054
A8: Alabama | B8: 2015 | C8: 977 | D8: Alabama 2015 | E8: 4727058 | F8: 0.00020668247
A9: Alabama | B9: 2016 | C9: 875 | D9: Alabama 2016 | E9: 4939554 | F9: 0.0001771415
A10: Alaska | B10: 2009 | C10: 0 | D10: Alaska 2009 | E10: 734628 | F10: 0
A11: Alaska | B11: 2010 | C11: 0 | D11: Alaska 2010 | E11: 702506 | F11: 0
A12: Alaska | B12: 2011 | C12: 0 | D12: Alaska 2011 | E12: 677432 | F12: 0
A13: Alaska | B13: 2012 | C13: 0 | D13: Alaska 2012 | E13: 675805 | F13: 0
... A336: South Dakota | B336: 2015 | C336: 82 | D336: South Dakota 2015 | E336: 657576 | F336: 0.00012470041
A337: South Dakota | B337: 2016 | C337: 70 | D337: South Dakota 2016 | E337: =AVERAGE(E330:E336) -> 759715.14 | F337: 0.00012470041
A338: Tennessee | B338: 2009 | C338: 1207 | D338: Tennessee 2009 | E338: 6056214 | F338: 0.00019929943
A339: Tennessee | B339: 2010 | C339: 1227 | D339: Tennessee 2010 | E339: 6268463 | F339: 0.00019574176
A340: Tennessee | B340: 2011 | C340: 1306 | D340: Tennessee 2011 | E340: 6341858 | F340: 0.00020593334
A341: Tennessee | B341: 2012 | C341: 1279 | D341: Tennessee 2012 | E341: 6331873 | F341: 0.00020199394
A342: Tennessee | B342: 2013 | C342: 1435 | D342: Tennessee 2013 | E342: 6184829 | F342: 0.00023201935
A343: Tennessee | B343: 2014 | C343: 1485 | D343: Tennessee 2014 | E343: 6516834 | F343: 0.00022787139
A344: Tennessee | B344: 2015 | C344: 1550 | D344: Tennessee 2015 | E344: 6469040 | F344: 0.00023960278
A345: Tennessee | B345: 2016 | C345: 1427 | D345: Tennessee 2016 | E345: =AVERAGE(E338:E344) -> 6309873 | F345: 0.00023960278
A346: Texas | B346: 2009 | C346: 3168 | D346: Texas 2009 | E346: 23721521 | F346: 0.00013354962
A347: Texas | B347: 2010 | C347: 2854 | D347: Texas 2010 | E347: 24172190 | F347: 0.00011806957
A348: Texas | B348: 2011 | C348: 2868 | D348: Texas 2011 | E348: 24819768 | F348: 0.00011555305
A349: Texas | B349: 2012 | C349: 2815 | D349: Texas 2012 | E349: 25037667 | F349: 0.0001124306
A350: Texas | B350: 2013 | C350: 3195 | D350: Texas 2013 | E350: 25684305 | F350: 0.00012439503
A351: Texas | B351: 2014 | C351: 3311 | D351: Texas 2014 | E351: 26011866 | F351: 0.00012728806
A352: Texas | B352: 2015 | C352: 3070 | D352: Texas 2015 | E352: 26071613 | F352: 0.00011775259
A353: Texas | B353: 2016 | C353: 2694 | D353: Texas 2016 | E353: =AVERAGE(E346:E352) -> 25074133 | F353: 0.00011775259
A354: Utah | B354: 2009 | C354: 120 | D354: Utah 2009 | E354: 2632280 | F354: 4.5587855e-05
A355: Utah | B355: 2010 | C355: 173 | D355: Utah 2010 | E355: 2665430 | F355: 6.49051e-05
A356: Utah | B356: 2011 | C356: 176 | D356: Utah 2011 | E356: 2672834 | F356: 6.5847711e-05
A357: Utah | B357: 2012 | C357: 157 | D357: Utah 2012 | E357: 2773327 | F357: 5.6610706e-05
A358: Utah | B358: 2013 | C358: 230 | D358: Utah 2013 | E358: 2938531 | F358: 7.8270401e-05
A359: Utah | B359: 2014 | C359: 186 | D359: Utah 2014 | E359: 2835421 | F359: 6.5598724e-05
A360: Utah | B360: 2015 | C360: 170 | D360: Utah 2015 | E360: 2906075 | F360: 5.8498146e-05
A361: Utah | B361: 2016 | C361: 183 | D361: Utah 2016 | E361: =AVERAGE(E354:E360) -> 2774842.6 | F361: 0.00015703155
A362: Vermont | B362: 2009 | C362: 0 | D362: Vermont 2009 | E362: 620414 | F362: 0
...

Sheet Statistics_analysis
A1: Data Spread
B2: Variable 1 | C2: Variable 2 | D2: Variable 3
A3: Data Name | B3: =Integrated_dataSet!C1 -> Deaths | C3: =Integrated_dataSet!E1 -> Population | D3: Rate
A4: Sample or Population? | B4: Population data | C4: Population data | D4: Population data
A5: Normal Distribution? | B5: =IF(ABS(SKEW(Integrated_dataSet!C2:C409))<1, "Yes", "No") -> No | C5: =IF(ABS(SKEW(Integrated_dataSet!E2:E409))<1, "Yes", "No") -> No | D5: =IF(ABS(SKEW(Integrated_dataSet!F2:F409))<1, "Yes", "No") -> Yes
A6: Variance | B6: =_xlfn.VAR.P(Integrated_dataSet!C2:C409) -> 1325082.6 | C6: =_xlfn.VAR.P(Integrated_dataSet!E2:E409) -> 4.614779e+13 | D6: =_xlfn.VAR.P(Integrated_dataSet!F2:F409) -> 4.1577746e-09
A7: Standard Deviation | B7: =_xlfn.STDEV.P(Integrated_dataSet!C2:C409) -> 1151.1223 | C7: =_xlfn.STDEV.P(Integrated_dataSet!E2:E409) -> 6793216.5 | D7: =_xlfn.STDEV.P(Integrated_dataSet!F2:F409) -> 6.4480808e-05
A8: Mean | B8: =AVERAGE(Integrated_dataSet!C2:C409) -> 900.2451 | C8: =AVERAGE(Integrated_dataSet!E2:E409) -> 6071162.5 | D8: =AVERAGE(Integrated_dataSet!F2:F409) -> 0.00012056588
A9: Outlier Percentage | B9: =B13/COUNT(Integrated_dataSet!C2:C409) -> 0.036764706 | C9: =C13/COUNT(Integrated_dataSet!E2:E409) -> 0.019607843 | D9: =D13/COUNT(Integrated_dataSet!F2:F409) -> 0.0024509804
A10: Lower Bound | B10: =B8-3*B7 -> -2553.1219 | C10: =C8-3*C7 -> -14308487 | D10: =D8-3*D7 -> -7.2876541e-05
A11: Upper Bound | B11: =B8+3*B7 -> 4353.6121 | C11: =C8+3*C7 -> 26450812 | D11: =D8+3*D7 -> 0.00031400831
A12: Outlier Flag | B12: =IF(OR(B2<B10,B2>B11),1,0) -> 1 | C12: =IF(OR(C2<C10,C2>C11),1,0) -> 1 | D12: =IF(OR(D2<D10,D2>D11),1,0) -> 1
A13: Outlier Count | B13: =COUNTIF(Integrated_dataSet!C2:C409,">" &B11) -> 15 | C13: =COUNTIF(Integrated_dataSet!E2:E409,">" &C11) -> 8 | D13: =COUNTIF(Integrated_dataSet!F2:F409,">" &D11) -> 1
A14: Correlation
A15: Variables | B15: Y | C15: X | D15: Deaths/Rate
A16: Proposed Relationship | B16: Deaths | C16: Population | D16: Rate
A17: Correlation Coefficient (Pearson R) | B17: =CORREL(Integrated_dataSet!E2:E409, Integrated_dataSet!C2:C409) -> 0.95683469 | D17: =CORREL(Integrated_dataSet!F2:F409, Integrated_dataSet!C2:C409) -> 0.52042253
A18: Strength of Correlation | B18: STRONG | D18: STRONG
A19: Usefulness / Interpretation | B19: Higher population associated with higher deaths | D19: Higher rate associated with higher deaths

Sheet Summary
B2: Summary:
B3: The dataset represents population-level state–year observations rather than a sample. Influenza mortality is measured using the variable Deaths, which serves as the dependent variable. Variance, standard deviation, mean, outlier counts, and correlation coefficients are computed directly from observed values. Correlation analysis quantifies the relationship between mortality counts and population size.
B9: Main points:
B10: -The dataset contains complete state–year records, indicating population data rather than a sample. -Influenza mortality is represented by the variable Deaths, used as the dependent variable. -Variance, standard deviation, and mean are calculated for Deaths in Statistics_analysis. -Outliers for Deaths are identified using the mean ± 3 standard deviations rule. -Population is analyzed as a second variable, with outlier counts and percentages computed. -Correlation between Deaths and Population is calculated and classified as strong.
